<?xml version="1.0"?>
<robot xmlns:xacro="http://www.ros.org/wiki/xacro">
  <xacro:macro name="diffbot" params="prefix"> 
  <link name="${prefix}base_link">
    <inertial>
      <origin
        xyz="0.0013688572752642 -3.87295500480427E-06 0.0927827830863319" rpy="0 0 0" />
      <mass value="13.5750139204526" />
      <inertia
        ixx="0.0564102799064398"
        ixy="9.98325007655309E-07"
        ixz="9.0688885223879E-06"
        iyy="0.089426465018141"
        iyz="-3.98089140010312E-07"
        izz="0.145520597685005" />
    </inertial>
    <visual>
      <origin xyz="0 0 0" rpy="0 0 0" />
      <geometry>
         <mesh filename="package://ai_bot/meshes/base_link.STL" />
      </geometry>
      <material
        name="">
        <color rgba="0.792156862745098 0.819607843137255 0.933333333333333 1" />
      </material>
    </visual>
    <collision>
      <origin xyz="0 0 0" rpy="0 0 0" />
      <geometry>
        <mesh filename="package://ai_bot/meshes/base_link.STL" />
      </geometry>
    </collision>
  </link>
  <!--Base footprint -->
  <link name="${prefix}base_footprint">
  </link>
  <joint name = "${prefix}base_footprint_joint" type = "fixed">
    <parent link = "${prefix}base_link"/>  
    <child link = "${prefix}base_footprint"/>   
    <origin xyz = "0 0 -0.05348" rpy = "0 0 0 "/>
  </joint> 
  <link name="${prefix}left_wheel">
    <inertial>
      <origin
        xyz="5.99895972520648E-11 0.00308508138880002 4.67024786898751E-11"
        rpy="0 0 0" />
      <mass value="0.0351746985822267" />
      <inertia
        ixx="1.52372278594292E-05"
        ixy="-2.44026276151976E-14"
        ixz="-4.72650666770404E-10"
        iyy="2.5785782200264E-05"
        iyz="-2.96383615882511E-14"
        izz="1.5236921243331E-05" />
    </inertial>
    <visual>
      <origin xyz="0 0 0" rpy="0 0 0" />
      <geometry>
        <mesh filename="package://ai_bot/meshes/left_wheel.STL" />
      </geometry>
      <material
        name="">
        <color
          rgba="0 0.717647058823529 0.968627450980392 1" />
      </material>
    </visual>
    <collision>
      <origin
        xyz="0 0 0"
        rpy="0 0 0" />
      <geometry>
        <mesh filename="package://ai_bot/meshes/left_wheel.STL" />
      </geometry>
    </collision>
  </link>
  <joint name="${prefix}left_wheel_joint" type="continuous">
    <origin
      xyz="0 0.118282956237309 -0.0194887930134312"
      rpy="0 0 0" />
    <parent
      link="${prefix}base_link" />
    <child
      link="${prefix}left_wheel" />
    <axis
      xyz="0 0.999986644638088 -0.00516822459438692" />
  </joint>
  <link name="${prefix}right_wheel">
    <inertial>
      <origin
        xyz="-6.92630423582118E-11 3.99186111999378E-05 3.13451140043775E-11" rpy="0 0 0" />
      <mass
        value="0.0351746985822267" />
      <inertia
        ixx="1.52369956767903E-05"
        ixy="-3.06672824358188E-14"
        ixz="4.90592305063557E-10"
        iyy="2.57857822002641E-05"
        iyz="2.30993485304775E-14"
        izz="1.52371534259708E-05" />
    </inertial>
    <visual>
      <origin
        xyz="0 0 0"
        rpy="0 0 0" />
      <geometry>
        <mesh filename="package://ai_bot/meshes/right_wheel.STL" />
      </geometry>
      <material
        name="">
        <color
          rgba="0 0.717647058823529 0.968627450980392 1" />
      </material>
    </visual>
    <collision>
      <origin
        xyz="0 0 0"
        rpy="0 0 0" />
      <geometry>
        <mesh filename="package://ai_bot/meshes/right_wheel.STL" />
      </geometry>
    </collision>
  </link>
  <joint name="${prefix}right_wheel_joint" type="continuous">
    <origin
      xyz="0 -0.12140795623731 -0.0182499999999998"
      rpy="0 0 0" />
    <parent link="${prefix}base_link" />
    <child link="${prefix}right_wheel" />
    <axis xyz="0 0.999986644638088 -0.00516822459438692" />
  </joint>
  <link name="${prefix}front_caster_wheel">
    <inertial>
      <origin
        xyz="-0.00300352392926367 -0.000142743096114694 0.005127272620834" rpy="0 0 0" />
      <mass value="0.00641735144998232" />
      <inertia
        ixx="4.40800200087676E-07"
        ixy="-8.19443299333736E-10"
        ixz="3.72180847716294E-08"
        iyy="5.26194591993747E-07"
        iyz="1.38929090259142E-09"
        izz="4.96672375617233E-07" />
    </inertial>
    <visual>
      <origin xyz="0 0 0" rpy="0 0 0" />
      <geometry>
        <mesh filename="package://ai_bot/meshes/front_caster_wheel.STL" />
      </geometry>
      <material
        name="">
        <color rgba="0.745098039215686 0.737254901960784 0.729411764705882 1" />
      </material>
    </visual>
    <collision>
      <origin
        xyz="0 0 0"
        rpy="0 0 0" />
      <geometry>
        <mesh filename="package://ai_bot/meshes/front_caster_wheel.STL" />
      </geometry>
    </collision>
  </link>
  <joint name="${prefix}front_caster_wheel_joint" type="fixed">
    <origin
      xyz="0.131975 -2.50000000001395E-05 -0.032622434610445"
      rpy="0 0 0" />
    <parent
      link="${prefix}base_link" />
    <child
      link="${prefix}front_caster_wheel" />
    <axis
      xyz="0 0 0" />
  </joint>
  <link
    name="${prefix}behide_caster_wheel">
    <inertial>
      <origin
        xyz="0.00300352392926367 0.000142743096114706 0.00512727262083399"
        rpy="0 0 0" />
      <mass value="0.00641735144998227" />
      <inertia
        ixx="4.40800200087671E-07"
        ixy="-8.19443299335529E-10"
        ixz="-3.72180847716286E-08"
        iyy="5.26194591993742E-07"
        iyz="-1.38929090259217E-09"
        izz="4.96672375617229E-07" />
    </inertial>
    <visual>
      <origin
        xyz="0 0 0"
        rpy="0 0 0" />
      <geometry>
        <mesh filename="package://ai_bot/meshes/behide_caster_wheel.STL" />
      </geometry>
      <material
        name="">
        <color rgba="0.745098039215686 0.737254901960784 0.729411764705882 1" />
      </material>
    </visual>
    <collision>
      <origin
        xyz="0 0 0"
        rpy="0 0 0" />
      <geometry>
        <mesh filename="package://ai_bot/meshes/behide_caster_wheel.STL" />
      </geometry>
    </collision>
  </link>
  <joint name="${prefix}behide_caster_wheel_joint" type="fixed">
    <origin
      xyz="-0.132025 -2.49999999998307E-05 -0.032622434610445"
      rpy="0 0 0" />
    <parent link="${prefix}base_link" />
    <child link="${prefix}behide_caster_wheel" />
    <axis
      xyz="0 0 0" />
  </joint>
  <link name="${prefix}camera_link">
    <inertial>
      <origin
        xyz="0.0115558872610029 5.1461901058219E-05 -0.000135983804464807"
        rpy="0 0 0" />
      <mass
        value="0.107910976062395" />
      <inertia
        ixx="7.12548338007056E-05"
        ixy="2.02378890458557E-07"
        ixz="4.92238184188486E-08"
        iyy="7.71085954680032E-06"
        iyz="-7.85497843430946E-11"
        izz="7.02570514208638E-05" />
    </inertial>
    <visual>
      <origin
        xyz="0 0 0"
        rpy="0 0 0" />
      <geometry>
        <mesh filename="package://ai_bot/meshes/camera_link.STL" />
      </geometry>
      <material
        name="">
        <color
          rgba="0.898039215686275 0.917647058823529 0.929411764705882 1" />
      </material>
    </visual>
    <collision>
      <origin
        xyz="0 0 0"
        rpy="0 0 0" />
      <geometry>
        <mesh filename="package://ai_bot/meshes/camera_link.STL" />
      </geometry>
    </collision>
  </link>
  <joint name="${prefix}camera_link_joint" type="fixed">
    <origin
      xyz="0.130430722828835 0.000158567751756303 0.145170466792632"
      rpy="0 -0.26179938779915 -0.00358936713377252" />
    <parent link="${prefix}base_link" />
    <child link="${prefix}camera_link" />
    <axis
      xyz="0 0 1" />
  </joint>
  <link name="${prefix}laser_link">
    <inertial>
      <origin
        xyz="-0.00165914147392161 1.23592808066667E-05 -0.0190714813330279"
        rpy="0 0 0" />
      <mass
        value="0.142947282569716" />
      <inertia
        ixx="8.18985503510344E-05"
        ixy="-3.57914467547389E-11"
        ixz="3.41316014484454E-07"
        iyy="8.22600717393491E-05"
        iyz="4.90965437966037E-08"
        izz="4.86431638141551E-05" />
    </inertial>
    <visual>
      <origin
        xyz="0 0 0"
        rpy="0 0 0" />
      <geometry>
        <mesh filename="package://ai_bot/meshes/laser_link.STL" />
      </geometry>
      <material
        name="">
        <color rgba="0.282352941176471 0.27843137254902 0.23921568627451 1" />
      </material>
    </visual>
    <collision>
      <origin
        xyz="0 0 0"
        rpy="0 0 0" />
      <geometry>
        <mesh filename="package://ai_bot/meshes/laser_link.STL" />
      </geometry>
    </collision>
  </link>
  <joint name="${prefix}laser_link_joint" type="fixed">
    <origin
      xyz="0.117338129115944 0.000799999999999963 0.26925"
      rpy="0 0 0" />
    <parent link="${prefix}base_link" />
    <child link="${prefix}laser_link" />
    <axis xyz="0 0 0" />
  </joint>
  <link name="${prefix}imu_link">
    <inertial>
      <origin
        xyz="0.000337950864787065 0.000243898911057139 -0.00130420688882585"
        rpy="0 0 0" />
      <mass value="0.000351250881223521" />
      <inertia
        ixx="9.45690179472922E-09"
        ixy="-2.68793364810256E-13"
        ixz="-3.07728741222328E-26"
        iyy="5.23526656779838E-09"
        iyz="1.73192945410136E-25"
        izz="1.46360849067925E-08" />
    </inertial>
    <visual>
      <origin
        xyz="0 0 0"
        rpy="0 0 0" />
      <geometry>
        <mesh filename="package://ai_bot/meshes/imu_link.STL" />
      </geometry>
      <material
        name="">
        <color
          rgba="0.964705882352941 0.964705882352941 0.952941176470588 1" />
      </material>
    </visual>
    <collision>
      <origin
        xyz="0 0 0"
        rpy="0 0 0" />
      <geometry>
        <mesh filename="package://ai_bot/meshes/imu_link.STL" />
      </geometry>
    </collision>
  </link>
  <joint name="${prefix}imu_link_joint" type="fixed">
    <origin
      xyz="0.042122668431236 0.0497822771736583 0.187"
      rpy="0 0 0" />
    <parent link="${prefix}base_link" />
    <child link="${prefix}imu_link" />
    <axis
      xyz="0 0 0" />
  </joint>
  </xacro:macro> 
</robot>