<?xml version="1.0"?>
<robot xmlns:xacro="http://www.ros.org/wiki/xacro">
  <xacro:macro name="diffbot" params="prefix"> 

  <link name="${prefix}base_link">
    <inertial>
      <origin
        xyz="0.0013688572752642 -3.87295500480382E-06 0.0927827830863319"
        rpy="0 0 0" />
      <mass
        value="13.5750139204526" />
      <inertia
        ixx="0.0564102799064398"
        ixy="9.98325007654513E-07"
        ixz="9.0688885223879E-06"
        iyy="0.089426465018141"
        iyz="-3.98089140010309E-07"
        izz="0.145520597685005" />
    </inertial>
    <visual>
      <origin xyz="0 0 0" rpy="0 0 0" />
      <geometry>
        <mesh
          filename="package://ai_bot/meshes/base_link2.STL" />
      </geometry>
      <material
        name="">
        <color
          rgba="0.792156862745098 0.819607843137255 0.933333333333333 1" />
      </material>
    </visual>
    <collision>
      <origin
        xyz="0 0 0"
        rpy="0 0 0" />
      <geometry>
        <mesh
          filename="package://ai_bot/meshes/base_link2.STL" />
      </geometry>
    </collision>
  </link>
  <!--Base footprint -->
  <joint name = "${prefix}base_footprint_joint" type = "fixed">
    <parent link = "${prefix}base_link"/>
    <child link = "${prefix}base_footprint"/>
    <origin xyz = "0 0 0" rpy = "0 0 0 "/>
  </joint> 
  <link name="${prefix}base_footprint">
  </link>
  <link name="${prefix}left_wheel">
    <inertial>
      <origin
        xyz="5.9989E-11 0.0030851 4.6703E-11"
        rpy="0 0 0" />
      <mass
        value="0.035175" />
      <inertia
        ixx="1.5237E-05"
        ixy="-2.4403E-14"
        ixz="-4.7265E-10"
        iyy="2.5786E-05"
        iyz="-2.964E-14"
        izz="1.5237E-05" />
    </inertial>
    <visual>
      <origin
        xyz="0 0 0"
        rpy="0 0 0" />
      <geometry>
        <mesh
          filename="package://ai_bot/meshes/left_wheel2.STL" />
      </geometry>
      <material
        name="">
        <color
          rgba="0 0.71765 0.96863 1" />
      </material>
    </visual>
    <collision>
      <origin
        xyz="0 0 0"
        rpy="0 0 0" />
      <geometry>
        <mesh
          filename="package://ai_bot/meshes/left_wheel2.STL" />
      </geometry>
    </collision>
  </link>
  <joint
    name="${prefix}left_wheel_joint"
    type="continuous">
    <origin
      xyz="0 0.118282956237309 -0.0194887930134312"
      rpy="0 0 0" />
    <parent
      link="${prefix}base_link" />
    <child
      link="${prefix}left_wheel" />
    <axis
      xyz="0 0.999986644638088 -0.00516822459438692" />
  </joint>
  <link
    name="${prefix}right_wheel">
    <inertial>
      <origin
        xyz="-6.9263E-11 3.9919E-05 3.1345E-11"
        rpy="0 0 0" />
      <mass
        value="0.035175" />
      <inertia
        ixx="1.5237E-05"
        ixy="-3.0667E-14"
        ixz="4.9059E-10"
        iyy="2.5786E-05"
        iyz="2.3099E-14"
        izz="1.5237E-05" />
    </inertial>
    <visual>
      <origin
        xyz="0 0 0"
        rpy="0 0 0" />
      <geometry>
        <mesh
          filename="package://ai_bot/meshes/right_wheel2.STL" />
      </geometry>
      <material
        name="">
        <color
          rgba="0 0.71765 0.96863 1" />
      </material>
    </visual>
    <collision>
      <origin
        xyz="0 0 0"
        rpy="0 0 0" />
      <geometry>
        <mesh
          filename="package://ai_bot/meshes/right_wheel2.STL" />
      </geometry>
    </collision>
  </link>
  <joint
    name="${prefix}right_wheel_joint"
    type="continuous">
    <origin
      xyz="0 -0.12140795623731 -0.0182499999999998"
      rpy="0 0 0" />
    <parent
      link="${prefix}base_link" />
    <child
      link="${prefix}right_wheel" />
    <axis
      xyz="0 0.999986644638088 -0.00516822459438692" />
  </joint>
  <link
    name="${prefix}front_caster_wheel">
    <inertial>
      <origin
        xyz="-0.0030035 -0.00014274 0.0051273"
        rpy="0 0 0" />
      <mass
        value="0.0064174" />
      <inertia
        ixx="4.408E-07"
        ixy="-8.1944E-10"
        ixz="3.7218E-08"
        iyy="5.2619E-07"
        iyz="1.3893E-09"
        izz="4.9667E-07" />
    </inertial>
    <visual>
      <origin
        xyz="0 0 0"
        rpy="0 0 0" />
      <geometry>
        <mesh
          filename="package://ai_bot/meshes/front_caster_wheel2.STL" />
      </geometry>
      <material
        name="">
        <color
          rgba="0.7451 0.73725 0.72941 1" />
      </material>
    </visual>
    <collision>
      <origin
        xyz="0 0 0"
        rpy="0 0 0" />
      <geometry>
        <mesh
          filename="package://ai_bot/meshes/front_caster_wheel2.STL" />
      </geometry>
    </collision>
  </link>
  <joint
    name="${prefix}front_caster_wheel_joint"
    type="fixed">
    <origin
      xyz="0.131975 -2.50000000001395E-05 -0.032622434610445"
      rpy="0 0 0" />
    <parent
      link="${prefix}base_link" />
    <child
      link="${prefix}front_caster_wheel" />
    <axis
      xyz="0 0 0" />
  </joint>
  <link
    name="${prefix}behide_caster_wheel">
    <inertial>
      <origin
        xyz="0.0030035 0.00014274 0.0051273"
        rpy="0 0 0" />
      <mass
        value="0.0064174" />
      <inertia
        ixx="4.408E-07"
        ixy="-8.1944E-10"
        ixz="-3.7218E-08"
        iyy="5.2619E-07"
        iyz="-1.3893E-09"
        izz="4.9667E-07" />
    </inertial>
    <visual>
      <origin
        xyz="0 0 0"
        rpy="0 0 0" />
      <geometry>
        <mesh
          filename="package://ai_bot/meshes/behide_caster_wheel2.STL" />
      </geometry>
      <material
        name="">
        <color
          rgba="0.7451 0.73725 0.72941 1" />
      </material>
    </visual>
    <collision>
      <origin
        xyz="0 0 0"
        rpy="0 0 0" />
      <geometry>
        <mesh
          filename="package://ai_bot/meshes/behide_caster_wheel2.STL" />
      </geometry>
    </collision>
  </link>
  <joint
    name="${prefix}behide_caster_wheel_joint"
    type="fixed">
    <origin
      xyz="-0.132025 -2.49999999998307E-05 -0.032622434610445"
      rpy="0 0 0" />
    <parent
      link="${prefix}base_link" />
    <child
      link="${prefix}behide_caster_wheel" />
    <axis
      xyz="0 0 0" />
  </joint>
  <link
    name="${prefix}camera_link">
    <inertial>
      <origin
        xyz="0.011556 5.1462E-05 -0.00013598"
        rpy="0 0 0" />
      <mass
        value="0.10791" />
      <inertia
        ixx="7.1255E-05"
        ixy="2.0238E-07"
        ixz="4.9224E-08"
        iyy="7.7109E-06"
        iyz="-7.855E-11"
        izz="7.0257E-05" />
    </inertial>
    <visual>
      <origin
        xyz="0 0 0"
        rpy="0 0 0" />
      <geometry>
        <mesh
          filename="package://ai_bot/meshes/camera_link2.STL" />
      </geometry>
      <material
        name="">
        <color
          rgba="0.89804 0.91765 0.92941 1" />
      </material>
    </visual>
    <collision>
      <origin
        xyz="0 0 0"
        rpy="0 0 0" />
      <geometry>
        <mesh
          filename="package://ai_bot/meshes/camera_link2.STL" />
      </geometry>
    </collision>
  </link>
  <joint
    name="${prefix}camera_link_joint"
    type="continuous">
    <origin
      xyz="0.130430722828835 0.000158567751756303 0.145170466792632"
      rpy="0 -0.26179938779915 -0.00358936713377252" />
    <parent
      link="${prefix}base_link" />
    <child
      link="${prefix}camera_link" />
    <axis
      xyz="0 0 1" />
  </joint>
  <link
    name="${prefix}laser_link">
    <inertial>
      <origin
        xyz="-0.0016591 1.2359E-05 -0.019071"
        rpy="0 0 0" />
      <mass
        value="0.14295" />
      <inertia
        ixx="8.1899E-05"
        ixy="-3.5791E-11"
        ixz="3.4132E-07"
        iyy="8.226E-05"
        iyz="4.9097E-08"
        izz="4.8643E-05" />
    </inertial>
    <visual>
      <origin
        xyz="0 0 0"
        rpy="0 0 0" />
      <geometry>
        <mesh
          filename="package://ai_bot/meshes/laser_link2.STL" />
      </geometry>
      <material
        name="">
        <color
          rgba="0.28235 0.27843 0.23922 1" />
      </material>
    </visual>
    <collision>
      <origin
        xyz="0 0 0"
        rpy="0 0 0" />
      <geometry>
        <mesh
          filename="package://ai_bot/meshes/laser_link2.STL" />
      </geometry>
    </collision>
  </link>
  <joint
    name="${prefix}laser_link_joint"
    type="fixed">
    <origin
      xyz="0.117338129115944 0.000799999999999963 0.26925"
      rpy="0 0 0" />
    <parent
      link="${prefix}base_link" />
    <child
      link="${prefix}laser_link" />
    <axis
      xyz="0 0 0" />
  </joint>
  </xacro:macro> 
</robot>
