<?xml version="1.0"?>
<robot xmlns:xacro="http://www.ros.org/wiki/xacro">
  <xacro:macro name="diffbot" params="prefix"> 
 
  <link name="${prefix}base_link">
    <inertial>
      <origin xyz="0.0011959066591067 3.19763511079794E-06 0.0790815210693337" rpy="0 0 0" />
      <mass value="13.9851806137402" />
      <inertia
        ixx="0.0565616036105733"
        ixy="1.74036626154324E-06"
        ixz="1.29045099103562E-05"
        iyy="0.0894862871568059"
        iyz="-3.17273323101069E-07"
        izz="0.145628464372461" />
    </inertial>
    <visual>
      <origin xyz="0 0 0" rpy="0 0 0" />
      <geometry>
        <mesh filename="package://ai_bot/meshes/base_link.STL" />
      </geometry>
      <material name="">
        <color rgba="0.792156862745098 0.819607843137255 0.933333333333333 1" />
      </material>
    </visual>
    <collision>
      <origin xyz="0 0 0" rpy="0 0 0" />
      <geometry>
        <mesh filename="package://ai_bot/meshes/base_link.STL" />
      </geometry>
    </collision>
  </link>

  <!--Base footprint -->
  <joint name = "${prefix}base_footprint_joint" type = "fixed">
    <parent link = "${prefix}base_link"/>
    <child link = "${prefix}base_footprint"/>
    <origin xyz = "0 0 0" rpy = "0 0 0 "/>
  </joint> 
  <link name="${prefix}base_footprint">
  </link>

  <link name="${prefix}left_wheel">
    <inertial>
      <origin xyz="1.4971626608403E-07 5.63997112901227E-11 -3.99183311016321E-05" rpy="0 0 0" />
      <mass value="0.0351746985874783" />
      <inertia
        ixx="1.52374010927882E-05"
        ixy="4.63884662445525E-10"
        ixz="-3.95742341078903E-08"
        iyy="1.52368964794531E-05"
        iyz="1.71185775853701E-12"
        izz="2.57856337288555E-05" />
    </inertial>
    <visual>
      <origin xyz="0 0 0" rpy="0 0 0" />
      <geometry>
        <mesh filename="package://ai_bot/meshes/left_wheel.STL" />
      </geometry>
      <material
        name="">
        <color rgba="0 0.717647058823529 0.968627450980392 1" />
      </material>
    </visual>
    <collision>
      <origin xyz="0 0 0" rpy="0 0 0" />
      <geometry>
        <mesh filename="package://ai_bot/meshes/left_wheel.STL" />
      </geometry>
    </collision>
  </link>
  <joint name="${prefix}left_wheel_joint" type="continuous">
    <origin xyz="0.00015616 0.12013 -0.01825" rpy="1.5708 0 3.1416" />
    <parent link="${prefix}base_link" />
    <child link="${prefix}left_wheel" />
    <axis xyz="0.00052824 0 1" />
  </joint>
  <link name="${prefix}right_wheel">
    <inertial>
      <origin xyz="2.31417876940358E-11 -7.24178703115363E-11 -3.99186111999794E-05"
        rpy="0 0 0" />
      <mass
        value="0.0351746985822266" />
      <inertia
        ixx="1.52375706319704E-05"
        ixy="2.83913263800806E-11"
        ixz="-3.40193683635414E-15"
        iyy="1.52365784708077E-05"
        iyz="3.82437348112352E-14"
        izz="2.57857822002642E-05" />
    </inertial>
    <visual>
      <origin
        xyz="0 0 0"
        rpy="0 0 0" />
      <geometry>
        <mesh
          filename="package://ai_bot/meshes/right_wheel.STL" />
      </geometry>
      <material
        name="">
        <color
          rgba="0 0.717647058823529 0.968627450980392 1" />
      </material>
    </visual>
    <collision>
      <origin
        xyz="0 0 0"
        rpy="0 0 0" />
      <geometry>
        <mesh
          filename="package://ai_bot/meshes/right_wheel.STL" />
      </geometry>
    </collision>
  </link>
  <joint
    name="${prefix}right_wheel_joint"
    type="continuous">
    <origin
      xyz="0.00028283 -0.11967 -0.01825"
      rpy="1.5708 0 0" />
    <parent
      link="${prefix}base_link" />
    <child
      link="${prefix}right_wheel" />
    <axis
      xyz="0.00052824 0 -1" />
  </joint>
  <link
    name="${prefix}front_caster_wheel">
    <inertial>
      <origin
        xyz="-0.00300352392924677 -0.000142743096146298 0.00512727262077545"
        rpy="0 0 0" />
      <mass
        value="0.00641735144994331" />
      <inertia
        ixx="4.40800200086495E-07"
        ixy="-8.19443298689714E-10"
        ixz="3.72180847716735E-08"
        iyy="5.26194591993215E-07"
        iyz="1.38929090263383E-09"
        izz="4.96672375615778E-07" />
    </inertial>
    <visual>
      <origin
        xyz="0 0 0"
        rpy="0 0 0" />
      <geometry>
        <mesh
          filename="package://ai_bot/meshes/front_caster_wheel.STL" />
      </geometry>
      <material
        name="">
        <color
          rgba="0.749019607843137 0.749019607843137 0.749019607843137 1" />
      </material>
    </visual>
    <collision>
      <origin
        xyz="0 0 0"
        rpy="0 0 0" />
      <geometry>
        <mesh
          filename="package://ai_bot/meshes/front_caster_wheel.STL" />
      </geometry>
    </collision>
  </link>
  <joint
    name="${prefix}front_caster_wheel_joint"
    type="fixed">
    <origin
      xyz="0.13203 2.5E-05 -0.038622"
      rpy="0 0 0" />
    <parent
      link="${prefix}base_link" />
    <child
      link="${prefix}front_caster_wheel" />
    <axis
      xyz="0 0 0" />
  </joint>
  <link
    name="${prefix}behide_caster_wheel">
    <inertial>
      <origin
        xyz="-0.0030035239292468 -0.000142743096146325 0.00512727262077543"
        rpy="0 0 0" />
      <mass
        value="0.00641735144994332" />
      <inertia
        ixx="4.40800200086496E-07"
        ixy="-8.19443298689479E-10"
        ixz="3.72180847716737E-08"
        iyy="5.26194591993216E-07"
        iyz="1.38929090263299E-09"
        izz="4.9667237561578E-07" />
    </inertial>
    <visual>
      <origin
        xyz="0 0 0"
        rpy="0 0 0" />
      <geometry>
        <mesh
          filename="package://ai_bot/meshes/behide_caster_wheel.STL" />
      </geometry>
      <material
        name="">
        <color
          rgba="0.745098039215686 0.737254901960784 0.729411764705882 1" />
      </material>
    </visual>
    <collision>
      <origin
        xyz="0 0 0"
        rpy="0 0 0" />
      <geometry>
        <mesh
          filename="package://ai_bot/meshes/behide_caster_wheel.STL" />
      </geometry>
    </collision>
  </link>
  <joint
    name="${prefix}behide_caster_wheel_joint"
    type="fixed">
    <origin
      xyz="-0.10803 2.5E-05 -0.038622"
      rpy="0 0 0" />
    <parent
      link="${prefix}base_link" />
    <child
      link="${prefix}behide_caster_wheel" />
    <axis
      xyz="0 0 0" />
  </joint>
  <link
    name="${prefix}camera_link">
    <inertial>
      <origin
        xyz="-0.00344402089430337 -0.00170906341489605 0.00213801456612586"
        rpy="0 0 0" />
      <mass
        value="0.107910426528219" />
      <inertia
        ixx="7.12550258584982E-05"
        ixy="-1.78478230851289E-08"
        ixz="4.92977758427115E-08"
        iyy="7.71002125333577E-06"
        iyz="2.48294328344241E-10"
        izz="7.02567365330472E-05" />
    </inertial>
    <visual>
      <origin
        xyz="0 0 0"
        rpy="0 0 0" />
      <geometry>
        <mesh
          filename="package://ai_bot/meshes/camera_link.STL" />
      </geometry>
      <material
        name="">
        <color
          rgba="0.898039215686275 0.917647058823529 0.929411764705882 1" />
      </material>
    </visual>
    <collision>
      <origin
        xyz="0 0 0"
        rpy="0 0 0" />
      <geometry>
        <mesh
          filename="package://ai_bot/meshes/camera_link.STL" />
      </geometry>
    </collision>
  </link>
  <joint
    name="${prefix}camera_link_joint"
    type="fixed">
    <origin
      xyz="0.12835 0 0.14019"
      rpy="0 0 0" />
    <parent
      link="${prefix}base_link" />
    <child
      link="${prefix}camera_link" />
    <axis
      xyz="0 0 0" />
  </joint>
  <link
    name="${prefix}laser_link">
    <inertial>
      <origin
        xyz="-0.000121012357978012 1.23592808066662E-05 0.032178518666972"
        rpy="0 0 0" />
      <mass
        value="0.142947282569716" />
      <inertia
        ixx="8.18985503510344E-05"
        ixy="-3.57914467517673E-11"
        ixz="3.41316014484444E-07"
        iyy="8.22600717393491E-05"
        iyz="4.90965437966037E-08"
        izz="4.86431638141551E-05" />
    </inertial>
    <visual>
      <origin
        xyz="0 0 0"
        rpy="0 0 0" />
      <geometry>
        <mesh
          filename="package://ai_bot/meshes/laser_link.STL" />
      </geometry>
      <material
        name="">
        <color
          rgba="0.282352941176471 0.27843137254902 0.23921568627451 1" />
      </material>
    </visual>
    <collision>
      <origin
        xyz="0 0 0"
        rpy="0 0 0" />
      <geometry>
        <mesh
          filename="package://ai_bot/meshes/laser_link.STL" />
      </geometry>
    </collision>
  </link>
  <joint
    name="${prefix}laser_link_joint"
    type="fixed">
    <origin
      xyz="0.1158 0.0008 0.212"
      rpy="0 0 0" />
    <parent
      link="${prefix}base_link" />
    <child
      link="${prefix}laser_link" />
    <axis
      xyz="0 0 0" />
  </joint>
   </xacro:macro> 
</robot>